[2024-01-31T11:27:02.248+0000] {taskinstance.py:1957} INFO - Dependencies all met for dep_context=non-requeueable deps ti=<TaskInstance: stock_analysis_dag.perform_descriptive_analysis manual__2024-01-31T11:26:50.645544+00:00 [queued]>
[2024-01-31T11:27:02.253+0000] {taskinstance.py:1957} INFO - Dependencies all met for dep_context=requeueable deps ti=<TaskInstance: stock_analysis_dag.perform_descriptive_analysis manual__2024-01-31T11:26:50.645544+00:00 [queued]>
[2024-01-31T11:27:02.253+0000] {taskinstance.py:2171} INFO - Starting attempt 1 of 3
[2024-01-31T11:27:02.263+0000] {taskinstance.py:2192} INFO - Executing <Task(PythonOperator): perform_descriptive_analysis> on 2024-01-31 11:26:50.645544+00:00
[2024-01-31T11:27:02.266+0000] {standard_task_runner.py:60} INFO - Started process 2583 to run task
[2024-01-31T11:27:02.268+0000] {standard_task_runner.py:87} INFO - Running: ['airflow', 'tasks', 'run', 'stock_analysis_dag', 'perform_descriptive_analysis', 'manual__2024-01-31T11:26:50.645544+00:00', '--job-id', '21', '--raw', '--subdir', 'DAGS_FOLDER/stock_analysis_dag.py', '--cfg-path', '/tmp/tmp7s5rse52']
[2024-01-31T11:27:02.269+0000] {standard_task_runner.py:88} INFO - Job 21: Subtask perform_descriptive_analysis
[2024-01-31T11:27:02.289+0000] {task_command.py:423} INFO - Running <TaskInstance: stock_analysis_dag.perform_descriptive_analysis manual__2024-01-31T11:26:50.645544+00:00 [running]> on host de-airflow-vm-instance-1.europe-west10-a.c.dataengineeringfinal-411911.internal
[2024-01-31T11:27:02.327+0000] {taskinstance.py:2481} INFO - Exporting env vars: AIRFLOW_CTX_DAG_EMAIL='onatpostac@gmail.com' AIRFLOW_CTX_DAG_OWNER='airflow' AIRFLOW_CTX_DAG_ID='stock_analysis_dag' AIRFLOW_CTX_TASK_ID='perform_descriptive_analysis' AIRFLOW_CTX_EXECUTION_DATE='2024-01-31T11:26:50.645544+00:00' AIRFLOW_CTX_TRY_NUMBER='1' AIRFLOW_CTX_DAG_RUN_ID='manual__2024-01-31T11:26:50.645544+00:00'
[2024-01-31T11:27:02.345+0000] {connection.py:234} WARNING - Connection schemes (type: google_cloud_platform) shall not contain '_' according to RFC3986.
[2024-01-31T11:27:02.346+0000] {base.py:83} INFO - Using connection ID 'google_cloud_default' for task execution.
[2024-01-31T11:27:02.608+0000] {taskinstance.py:2699} ERROR - Task failed with exception
Traceback (most recent call last):
  File "/home/deprojectue/miniconda3/envs/airflow_demo/lib/python3.9/site-packages/airflow/models/taskinstance.py", line 433, in _execute_task
    result = execute_callable(context=context, **execute_callable_kwargs)
  File "/home/deprojectue/miniconda3/envs/airflow_demo/lib/python3.9/site-packages/airflow/operators/python.py", line 199, in execute
    return_value = self.execute_callable()
  File "/home/deprojectue/miniconda3/envs/airflow_demo/lib/python3.9/site-packages/airflow/operators/python.py", line 216, in execute_callable
    return self.python_callable(*self.op_args, **self.op_kwargs)
  File "/home/deprojectue/airflow_demo/dags/stock_analysis_dag.py", line 156, in perform_descriptive_analysis
    raise Exception(f"Errors occurred while inserting statistics: {errors}")
Exception: Errors occurred while inserting statistics: [{'index': 0, 'errors': [{'reason': 'invalid', 'location': '4. close', 'debugInfo': '', 'message': 'no such field: 4. close.'}]}]
[2024-01-31T11:27:02.611+0000] {taskinstance.py:1138} INFO - Marking task as UP_FOR_RETRY. dag_id=stock_analysis_dag, task_id=perform_descriptive_analysis, execution_date=20240131T112650, start_date=20240131T112702, end_date=20240131T112702
[2024-01-31T11:27:02.620+0000] {standard_task_runner.py:107} ERROR - Failed to execute job 21 for task perform_descriptive_analysis (Errors occurred while inserting statistics: [{'index': 0, 'errors': [{'reason': 'invalid', 'location': '4. close', 'debugInfo': '', 'message': 'no such field: 4. close.'}]}]; 2583)
[2024-01-31T11:27:02.640+0000] {local_task_job_runner.py:234} INFO - Task exited with return code 1
[2024-01-31T11:27:02.648+0000] {taskinstance.py:3281} INFO - 0 downstream tasks scheduled from follow-on schedule check
