[2024-01-31T12:23:17.163+0000] {taskinstance.py:1957} INFO - Dependencies all met for dep_context=non-requeueable deps ti=<TaskInstance: stock_analysis_dag.perform_descriptive_analysis manual__2024-01-31T12:22:58.254749+00:00 [queued]>
[2024-01-31T12:23:17.167+0000] {taskinstance.py:1957} INFO - Dependencies all met for dep_context=requeueable deps ti=<TaskInstance: stock_analysis_dag.perform_descriptive_analysis manual__2024-01-31T12:22:58.254749+00:00 [queued]>
[2024-01-31T12:23:17.167+0000] {taskinstance.py:2171} INFO - Starting attempt 1 of 3
[2024-01-31T12:23:17.178+0000] {taskinstance.py:2192} INFO - Executing <Task(PythonOperator): perform_descriptive_analysis> on 2024-01-31 12:22:58.254749+00:00
[2024-01-31T12:23:17.181+0000] {standard_task_runner.py:60} INFO - Started process 3359 to run task
[2024-01-31T12:23:17.182+0000] {standard_task_runner.py:87} INFO - Running: ['airflow', 'tasks', 'run', 'stock_analysis_dag', 'perform_descriptive_analysis', 'manual__2024-01-31T12:22:58.254749+00:00', '--job-id', '49', '--raw', '--subdir', 'DAGS_FOLDER/stock_analysis_dag.py', '--cfg-path', '/tmp/tmpvjmg17b4']
[2024-01-31T12:23:17.183+0000] {standard_task_runner.py:88} INFO - Job 49: Subtask perform_descriptive_analysis
[2024-01-31T12:23:17.202+0000] {task_command.py:423} INFO - Running <TaskInstance: stock_analysis_dag.perform_descriptive_analysis manual__2024-01-31T12:22:58.254749+00:00 [running]> on host de-airflow-vm-instance-1.europe-west10-a.c.dataengineeringfinal-411911.internal
[2024-01-31T12:23:17.240+0000] {taskinstance.py:2481} INFO - Exporting env vars: AIRFLOW_CTX_DAG_EMAIL='onatpostac@gmail.com' AIRFLOW_CTX_DAG_OWNER='airflow' AIRFLOW_CTX_DAG_ID='stock_analysis_dag' AIRFLOW_CTX_TASK_ID='perform_descriptive_analysis' AIRFLOW_CTX_EXECUTION_DATE='2024-01-31T12:22:58.254749+00:00' AIRFLOW_CTX_TRY_NUMBER='1' AIRFLOW_CTX_DAG_RUN_ID='manual__2024-01-31T12:22:58.254749+00:00'
[2024-01-31T12:23:17.254+0000] {connection.py:234} WARNING - Connection schemes (type: google_cloud_platform) shall not contain '_' according to RFC3986.
[2024-01-31T12:23:17.254+0000] {base.py:83} INFO - Using connection ID 'google_cloud_default' for task execution.
[2024-01-31T12:23:17.432+0000] {taskinstance.py:2699} ERROR - Task failed with exception
Traceback (most recent call last):
  File "/home/deprojectue/miniconda3/envs/airflow_demo/lib/python3.9/site-packages/airflow/models/taskinstance.py", line 433, in _execute_task
    result = execute_callable(context=context, **execute_callable_kwargs)
  File "/home/deprojectue/miniconda3/envs/airflow_demo/lib/python3.9/site-packages/airflow/operators/python.py", line 199, in execute
    return_value = self.execute_callable()
  File "/home/deprojectue/miniconda3/envs/airflow_demo/lib/python3.9/site-packages/airflow/operators/python.py", line 216, in execute_callable
    return self.python_callable(*self.op_args, **self.op_kwargs)
  File "/home/deprojectue/airflow_demo/dags/stock_analysis_dag.py", line 216, in perform_descriptive_analysis
    errors = client.insert_rows_json(table_ref, transformed_data)
  File "/home/deprojectue/miniconda3/envs/airflow_demo/lib/python3.9/site-packages/google/cloud/bigquery/client.py", line 3778, in insert_rows_json
    response = self._call_api(
  File "/home/deprojectue/miniconda3/envs/airflow_demo/lib/python3.9/site-packages/google/cloud/bigquery/client.py", line 818, in _call_api
    return call()
  File "/home/deprojectue/miniconda3/envs/airflow_demo/lib/python3.9/site-packages/google/api_core/retry.py", line 372, in retry_wrapped_func
    return retry_target(
  File "/home/deprojectue/miniconda3/envs/airflow_demo/lib/python3.9/site-packages/google/api_core/retry.py", line 207, in retry_target
    result = target()
  File "/home/deprojectue/miniconda3/envs/airflow_demo/lib/python3.9/site-packages/google/cloud/_http/__init__.py", line 494, in api_request
    raise exceptions.from_http_response(response)
google.api_core.exceptions.NotFound: 404 POST https://bigquery.googleapis.com/bigquery/v2/projects/dataengineeringfinal-411911/datasets/ibm_stock/tables/ibm_statistics_table/insertAll?prettyPrint=false: Table is truncated.
[2024-01-31T12:23:17.436+0000] {taskinstance.py:1138} INFO - Marking task as UP_FOR_RETRY. dag_id=stock_analysis_dag, task_id=perform_descriptive_analysis, execution_date=20240131T122258, start_date=20240131T122317, end_date=20240131T122317
[2024-01-31T12:23:17.444+0000] {standard_task_runner.py:107} ERROR - Failed to execute job 49 for task perform_descriptive_analysis (404 POST https://bigquery.googleapis.com/bigquery/v2/projects/dataengineeringfinal-411911/datasets/ibm_stock/tables/ibm_statistics_table/insertAll?prettyPrint=false: Table is truncated.; 3359)
[2024-01-31T12:23:17.475+0000] {local_task_job_runner.py:234} INFO - Task exited with return code 1
[2024-01-31T12:23:17.485+0000] {taskinstance.py:3281} INFO - 0 downstream tasks scheduled from follow-on schedule check
