[2024-01-31T11:42:24.026+0000] {taskinstance.py:1957} INFO - Dependencies all met for dep_context=non-requeueable deps ti=<TaskInstance: stock_analysis_dag.perform_descriptive_analysis manual__2024-01-31T11:32:01.368384+00:00 [queued]>
[2024-01-31T11:42:24.031+0000] {taskinstance.py:1957} INFO - Dependencies all met for dep_context=requeueable deps ti=<TaskInstance: stock_analysis_dag.perform_descriptive_analysis manual__2024-01-31T11:32:01.368384+00:00 [queued]>
[2024-01-31T11:42:24.031+0000] {taskinstance.py:2171} INFO - Starting attempt 3 of 3
[2024-01-31T11:42:24.041+0000] {taskinstance.py:2192} INFO - Executing <Task(PythonOperator): perform_descriptive_analysis> on 2024-01-31 11:32:01.368384+00:00
[2024-01-31T11:42:24.044+0000] {standard_task_runner.py:60} INFO - Started process 2768 to run task
[2024-01-31T11:42:24.046+0000] {standard_task_runner.py:87} INFO - Running: ['airflow', 'tasks', 'run', 'stock_analysis_dag', 'perform_descriptive_analysis', 'manual__2024-01-31T11:32:01.368384+00:00', '--job-id', '31', '--raw', '--subdir', 'DAGS_FOLDER/stock_analysis_dag.py', '--cfg-path', '/tmp/tmp96m6kipu']
[2024-01-31T11:42:24.047+0000] {standard_task_runner.py:88} INFO - Job 31: Subtask perform_descriptive_analysis
[2024-01-31T11:42:24.069+0000] {task_command.py:423} INFO - Running <TaskInstance: stock_analysis_dag.perform_descriptive_analysis manual__2024-01-31T11:32:01.368384+00:00 [running]> on host de-airflow-vm-instance-1.europe-west10-a.c.dataengineeringfinal-411911.internal
[2024-01-31T11:42:24.109+0000] {taskinstance.py:2481} INFO - Exporting env vars: AIRFLOW_CTX_DAG_EMAIL='onatpostac@gmail.com' AIRFLOW_CTX_DAG_OWNER='airflow' AIRFLOW_CTX_DAG_ID='stock_analysis_dag' AIRFLOW_CTX_TASK_ID='perform_descriptive_analysis' AIRFLOW_CTX_EXECUTION_DATE='2024-01-31T11:32:01.368384+00:00' AIRFLOW_CTX_TRY_NUMBER='3' AIRFLOW_CTX_DAG_RUN_ID='manual__2024-01-31T11:32:01.368384+00:00'
[2024-01-31T11:42:24.124+0000] {connection.py:234} WARNING - Connection schemes (type: google_cloud_platform) shall not contain '_' according to RFC3986.
[2024-01-31T11:42:24.125+0000] {base.py:83} INFO - Using connection ID 'google_cloud_default' for task execution.
[2024-01-31T11:42:24.353+0000] {taskinstance.py:2699} ERROR - Task failed with exception
Traceback (most recent call last):
  File "/home/deprojectue/miniconda3/envs/airflow_demo/lib/python3.9/site-packages/airflow/models/taskinstance.py", line 433, in _execute_task
    result = execute_callable(context=context, **execute_callable_kwargs)
  File "/home/deprojectue/miniconda3/envs/airflow_demo/lib/python3.9/site-packages/airflow/operators/python.py", line 199, in execute
    return_value = self.execute_callable()
  File "/home/deprojectue/miniconda3/envs/airflow_demo/lib/python3.9/site-packages/airflow/operators/python.py", line 216, in execute_callable
    return self.python_callable(*self.op_args, **self.op_kwargs)
  File "/home/deprojectue/airflow_demo/dags/stock_analysis_dag.py", line 164, in perform_descriptive_analysis
    raise Exception(f"Errors occurred while inserting statistics: {errors}")
Exception: Errors occurred while inserting statistics: [{'index': 0, 'errors': [{'reason': 'invalid', 'location': 'open', 'debugInfo': '', 'message': 'no such field: open.'}]}]
[2024-01-31T11:42:24.356+0000] {taskinstance.py:1138} INFO - Marking task as FAILED. dag_id=stock_analysis_dag, task_id=perform_descriptive_analysis, execution_date=20240131T113201, start_date=20240131T114224, end_date=20240131T114224
[2024-01-31T11:42:24.364+0000] {logging_mixin.py:188} WARNING - /home/deprojectue/miniconda3/envs/airflow_demo/lib/python3.9/site-packages/airflow/utils/email.py:154 RemovedInAirflow3Warning: Fetching SMTP credentials from configuration variables will be deprecated in a future release. Please set credentials using a connection instead.
[2024-01-31T11:42:24.364+0000] {configuration.py:1046} WARNING - section/key [smtp/smtp_user] not found in config
[2024-01-31T11:42:24.364+0000] {email.py:270} INFO - Email alerting: attempt 1
[2024-01-31T11:42:25.076+0000] {email.py:281} INFO - Sent an alert email to ['onatpostac@gmail.com']
[2024-01-31T11:42:25.132+0000] {standard_task_runner.py:107} ERROR - Failed to execute job 31 for task perform_descriptive_analysis (Errors occurred while inserting statistics: [{'index': 0, 'errors': [{'reason': 'invalid', 'location': 'open', 'debugInfo': '', 'message': 'no such field: open.'}]}]; 2768)
[2024-01-31T11:42:25.140+0000] {local_task_job_runner.py:234} INFO - Task exited with return code 1
[2024-01-31T11:42:25.148+0000] {taskinstance.py:3281} INFO - 0 downstream tasks scheduled from follow-on schedule check
