[2024-01-31T10:15:32.461+0000] {taskinstance.py:1957} INFO - Dependencies all met for dep_context=non-requeueable deps ti=<TaskInstance: stock_analysis_dag.process_stock_data manual__2024-01-31T10:15:23.289105+00:00 [queued]>
[2024-01-31T10:15:32.465+0000] {taskinstance.py:1957} INFO - Dependencies all met for dep_context=requeueable deps ti=<TaskInstance: stock_analysis_dag.process_stock_data manual__2024-01-31T10:15:23.289105+00:00 [queued]>
[2024-01-31T10:15:32.465+0000] {taskinstance.py:2171} INFO - Starting attempt 1 of 3
[2024-01-31T10:15:32.477+0000] {taskinstance.py:2192} INFO - Executing <Task(PythonOperator): process_stock_data> on 2024-01-31 10:15:23.289105+00:00
[2024-01-31T10:15:32.480+0000] {standard_task_runner.py:60} INFO - Started process 2045 to run task
[2024-01-31T10:15:32.482+0000] {standard_task_runner.py:87} INFO - Running: ['airflow', 'tasks', 'run', 'stock_analysis_dag', 'process_stock_data', 'manual__2024-01-31T10:15:23.289105+00:00', '--job-id', '8', '--raw', '--subdir', 'DAGS_FOLDER/stock_analysis_dag.py', '--cfg-path', '/tmp/tmp9dsp9bml']
[2024-01-31T10:15:32.484+0000] {standard_task_runner.py:88} INFO - Job 8: Subtask process_stock_data
[2024-01-31T10:15:32.505+0000] {task_command.py:423} INFO - Running <TaskInstance: stock_analysis_dag.process_stock_data manual__2024-01-31T10:15:23.289105+00:00 [running]> on host de-airflow-vm-instance-1.europe-west10-a.c.dataengineeringfinal-411911.internal
[2024-01-31T10:15:32.543+0000] {taskinstance.py:2481} INFO - Exporting env vars: AIRFLOW_CTX_DAG_EMAIL='onatpostac@gmail.com' AIRFLOW_CTX_DAG_OWNER='airflow' AIRFLOW_CTX_DAG_ID='stock_analysis_dag' AIRFLOW_CTX_TASK_ID='process_stock_data' AIRFLOW_CTX_EXECUTION_DATE='2024-01-31T10:15:23.289105+00:00' AIRFLOW_CTX_TRY_NUMBER='1' AIRFLOW_CTX_DAG_RUN_ID='manual__2024-01-31T10:15:23.289105+00:00'
[2024-01-31T10:15:32.564+0000] {connection.py:234} WARNING - Connection schemes (type: google_cloud_platform) shall not contain '_' according to RFC3986.
[2024-01-31T10:15:32.565+0000] {base.py:83} INFO - Using connection ID 'google_cloud_default' for task execution.
[2024-01-31T10:15:32.567+0000] {taskinstance.py:2699} ERROR - Task failed with exception
Traceback (most recent call last):
  File "/home/deprojectue/miniconda3/envs/airflow_demo/lib/python3.9/site-packages/airflow/models/taskinstance.py", line 433, in _execute_task
    result = execute_callable(context=context, **execute_callable_kwargs)
  File "/home/deprojectue/miniconda3/envs/airflow_demo/lib/python3.9/site-packages/airflow/operators/python.py", line 199, in execute
    return_value = self.execute_callable()
  File "/home/deprojectue/miniconda3/envs/airflow_demo/lib/python3.9/site-packages/airflow/operators/python.py", line 216, in execute_callable
    return self.python_callable(*self.op_args, **self.op_kwargs)
  File "/home/deprojectue/airflow_demo/dags/stock_analysis_dag.py", line 102, in process_stock_data
    errors = client.insert_rows_json(table_ref, records)
  File "/home/deprojectue/miniconda3/envs/airflow_demo/lib/python3.9/site-packages/google/cloud/bigquery/client.py", line 3778, in insert_rows_json
    response = self._call_api(
  File "/home/deprojectue/miniconda3/envs/airflow_demo/lib/python3.9/site-packages/google/cloud/bigquery/client.py", line 818, in _call_api
    return call()
  File "/home/deprojectue/miniconda3/envs/airflow_demo/lib/python3.9/site-packages/google/api_core/retry.py", line 372, in retry_wrapped_func
    return retry_target(
  File "/home/deprojectue/miniconda3/envs/airflow_demo/lib/python3.9/site-packages/google/api_core/retry.py", line 207, in retry_target
    result = target()
  File "/home/deprojectue/miniconda3/envs/airflow_demo/lib/python3.9/site-packages/google/cloud/_http/__init__.py", line 479, in api_request
    data = json.dumps(data)
  File "/home/deprojectue/miniconda3/envs/airflow_demo/lib/python3.9/json/__init__.py", line 231, in dumps
    return _default_encoder.encode(obj)
  File "/home/deprojectue/miniconda3/envs/airflow_demo/lib/python3.9/json/encoder.py", line 199, in encode
    chunks = self.iterencode(o, _one_shot=True)
  File "/home/deprojectue/miniconda3/envs/airflow_demo/lib/python3.9/json/encoder.py", line 257, in iterencode
    return _iterencode(o, 0)
  File "/home/deprojectue/miniconda3/envs/airflow_demo/lib/python3.9/json/encoder.py", line 179, in default
    raise TypeError(f'Object of type {o.__class__.__name__} '
TypeError: Object of type Timestamp is not JSON serializable
[2024-01-31T10:15:32.572+0000] {taskinstance.py:1138} INFO - Marking task as UP_FOR_RETRY. dag_id=stock_analysis_dag, task_id=process_stock_data, execution_date=20240131T101523, start_date=20240131T101532, end_date=20240131T101532
[2024-01-31T10:15:32.581+0000] {standard_task_runner.py:107} ERROR - Failed to execute job 8 for task process_stock_data (Object of type Timestamp is not JSON serializable; 2045)
[2024-01-31T10:15:32.614+0000] {local_task_job_runner.py:234} INFO - Task exited with return code 1
[2024-01-31T10:15:32.622+0000] {taskinstance.py:3281} INFO - 0 downstream tasks scheduled from follow-on schedule check
