[2024-01-31T02:16:57.516+0000] {taskinstance.py:1957} INFO - Dependencies all met for dep_context=non-requeueable deps ti=<TaskInstance: stock_analysis_dag.is_alpha_vantage_api_ready manual__2024-01-31T02:14:26.812867+00:00 [queued]>
[2024-01-31T02:16:57.547+0000] {taskinstance.py:1957} INFO - Dependencies all met for dep_context=requeueable deps ti=<TaskInstance: stock_analysis_dag.is_alpha_vantage_api_ready manual__2024-01-31T02:14:26.812867+00:00 [queued]>
[2024-01-31T02:16:57.548+0000] {taskinstance.py:2171} INFO - Starting attempt 1 of 3
[2024-01-31T02:16:58.044+0000] {taskinstance.py:2192} INFO - Executing <Task(HttpSensor): is_alpha_vantage_api_ready> on 2024-01-31 02:14:26.812867+00:00
[2024-01-31T02:16:58.267+0000] {standard_task_runner.py:60} INFO - Started process 211182 to run task
[2024-01-31T02:16:58.495+0000] {standard_task_runner.py:87} INFO - Running: ['airflow', 'tasks', 'run', 'stock_analysis_dag', 'is_alpha_vantage_api_ready', 'manual__2024-01-31T02:14:26.812867+00:00', '--job-id', '4', '--raw', '--subdir', 'DAGS_FOLDER/stock_analysis_dag.py', '--cfg-path', '/tmp/tmpwbkxihyl']
[2024-01-31T02:16:58.497+0000] {standard_task_runner.py:88} INFO - Job 4: Subtask is_alpha_vantage_api_ready
[2024-01-31T02:18:27.517+0000] {task_command.py:423} INFO - Running <TaskInstance: stock_analysis_dag.is_alpha_vantage_api_ready manual__2024-01-31T02:14:26.812867+00:00 [running]> on host de-airflow-vm-instance-1.europe-west10-a.c.dataengineeringfinal-411911.internal
[2024-01-31T02:19:15.782+0000] {process_utils.py:131} INFO - Sending Signals.SIGTERM to group 211182. PIDs of all processes in the group: [211182]
[2024-01-31T02:19:16.010+0000] {process_utils.py:86} INFO - Sending the signal Signals.SIGTERM to group 211182
[2024-01-31T02:19:16.021+0000] {taskinstance.py:2451} ERROR - Received SIGTERM. Terminating subprocesses.
[2024-01-31T02:19:16.040+0000] {taskinstance.py:2699} ERROR - Task failed with exception
Traceback (most recent call last):
  File "/home/deprojectue/miniconda3/envs/airflow_demo/lib/python3.9/site-packages/airflow/models/taskinstance.py", line 2335, in _run_raw_task
    self._execute_task_with_callbacks(context, test_mode, session=session)
  File "/home/deprojectue/miniconda3/envs/airflow_demo/lib/python3.9/site-packages/airflow/models/taskinstance.py", line 2470, in _execute_task_with_callbacks
    RenderedTaskInstanceFields.write(rtif)
  File "/home/deprojectue/miniconda3/envs/airflow_demo/lib/python3.9/site-packages/airflow/utils/session.py", line 79, in wrapper
    return func(*args, session=session, **kwargs)
  File "/home/deprojectue/miniconda3/envs/airflow_demo/lib/python3.9/site-packages/airflow/utils/retries.py", line 91, in wrapped_function
    for attempt in run_with_db_retries(max_retries=retries, logger=logger, **retry_kwargs):
  File "/home/deprojectue/miniconda3/envs/airflow_demo/lib/python3.9/site-packages/tenacity/__init__.py", line 347, in __iter__
    do = self.iter(retry_state=retry_state)
  File "/home/deprojectue/miniconda3/envs/airflow_demo/lib/python3.9/site-packages/tenacity/__init__.py", line 314, in iter
    return fut.result()
  File "/home/deprojectue/miniconda3/envs/airflow_demo/lib/python3.9/concurrent/futures/_base.py", line 439, in result
    return self.__get_result()
  File "/home/deprojectue/miniconda3/envs/airflow_demo/lib/python3.9/concurrent/futures/_base.py", line 391, in __get_result
    raise self._exception
  File "/home/deprojectue/miniconda3/envs/airflow_demo/lib/python3.9/site-packages/airflow/utils/retries.py", line 100, in wrapped_function
    return func(*args, **kwargs)
  File "/home/deprojectue/miniconda3/envs/airflow_demo/lib/python3.9/site-packages/airflow/models/renderedtifields.py", line 192, in write
    session.merge(self)
  File "/home/deprojectue/miniconda3/envs/airflow_demo/lib/python3.9/site-packages/sqlalchemy/orm/session.py", line 3056, in merge
    return self._merge(
  File "/home/deprojectue/miniconda3/envs/airflow_demo/lib/python3.9/site-packages/sqlalchemy/orm/session.py", line 3136, in _merge
    merged = self.get(
  File "/home/deprojectue/miniconda3/envs/airflow_demo/lib/python3.9/site-packages/sqlalchemy/orm/session.py", line 2853, in get
    return self._get_impl(
  File "/home/deprojectue/miniconda3/envs/airflow_demo/lib/python3.9/site-packages/sqlalchemy/orm/session.py", line 2975, in _get_impl
    return db_load_fn(
  File "/home/deprojectue/miniconda3/envs/airflow_demo/lib/python3.9/site-packages/sqlalchemy/orm/loading.py", line 530, in load_on_pk_identity
    session.execute(
  File "/home/deprojectue/miniconda3/envs/airflow_demo/lib/python3.9/site-packages/sqlalchemy/orm/session.py", line 1717, in execute
    result = conn._execute_20(statement, params or {}, execution_options)
  File "/home/deprojectue/miniconda3/envs/airflow_demo/lib/python3.9/site-packages/sqlalchemy/engine/base.py", line 1710, in _execute_20
    return meth(self, args_10style, kwargs_10style, execution_options)
  File "/home/deprojectue/miniconda3/envs/airflow_demo/lib/python3.9/site-packages/sqlalchemy/sql/elements.py", line 334, in _execute_on_connection
    return connection._execute_clauseelement(
  File "/home/deprojectue/miniconda3/envs/airflow_demo/lib/python3.9/site-packages/sqlalchemy/engine/base.py", line 1577, in _execute_clauseelement
    ret = self._execute_context(
  File "/home/deprojectue/miniconda3/envs/airflow_demo/lib/python3.9/site-packages/sqlalchemy/engine/base.py", line 1953, in _execute_context
    self._handle_dbapi_exception(
  File "/home/deprojectue/miniconda3/envs/airflow_demo/lib/python3.9/site-packages/sqlalchemy/engine/base.py", line 2138, in _handle_dbapi_exception
    util.raise_(exc_info[1], with_traceback=exc_info[2])
  File "/home/deprojectue/miniconda3/envs/airflow_demo/lib/python3.9/site-packages/sqlalchemy/util/compat.py", line 211, in raise_
    raise exception
  File "/home/deprojectue/miniconda3/envs/airflow_demo/lib/python3.9/site-packages/sqlalchemy/engine/base.py", line 1910, in _execute_context
    self.dialect.do_execute(
  File "/home/deprojectue/miniconda3/envs/airflow_demo/lib/python3.9/site-packages/sqlalchemy/engine/default.py", line 736, in do_execute
    cursor.execute(statement, parameters)
  File "/home/deprojectue/miniconda3/envs/airflow_demo/lib/python3.9/site-packages/airflow/models/taskinstance.py", line 2453, in signal_handler
    raise AirflowException("Task received SIGTERM signal")
airflow.exceptions.AirflowException: Task received SIGTERM signal
[2024-01-31T02:19:16.505+0000] {taskinstance.py:1138} INFO - Marking task as UP_FOR_RETRY. dag_id=stock_analysis_dag, task_id=is_alpha_vantage_api_ready, execution_date=20240131T021426, start_date=20240131T021657, end_date=20240131T021916
[2024-01-31T02:19:16.795+0000] {standard_task_runner.py:107} ERROR - Failed to execute job 4 for task is_alpha_vantage_api_ready (Task received SIGTERM signal; 211182)
[2024-01-31T02:19:17.044+0000] {process_utils.py:79} INFO - Process psutil.Process(pid=211182, status='terminated', exitcode=1, started='02:16:57') (211182) terminated with exit code 1
